Workbook
Name Slicer_Department: #N/A
Name Slicer_State: #N/A

Sheet Date
A1: Date Delivered | B1: Day name | C1: Day num | D1: Month Name | E1: Month Num
A2: 45392 | B2: Wednesday | C2: 10 | D2: April | E2: 4
A3: 45369 | B3: Monday | C3: 18 | D3: March | E3: 3
A4: 45327 | B4: Monday | C4: 5 | D4: February | E4: 2
A5: 45407 | B5: Thursday | C5: 25 | D5: April | E5: 4
A6: 45379 | B6: Thursday | C6: 28 | D6: March | E6: 3
A7: 45417 | B7: Sunday | C7: 5 | D7: May | E7: 5
A8: 45376 | B8: Monday | C8: 25 | D8: March | E8: 3
A9: 45397 | B9: Monday | C9: 15 | D9: April | E9: 4
A10: 45342 | B10: Tuesday | C10: 20 | D10: February | E10: 2
A11: 45412 | B11: Tuesday | C11: 30 | D11: April | E11: 4
A12: 45387 | B12: Friday | C12: 5 | D12: April | E12: 4
A13: 45361 | B13: Sunday | C13: 10 | D13: March | E13: 3
... A20: 45394 | B20: Friday | C20: 12 | D20: April | E20: 4

Sheet Sheet1

Sheet Procurement Data
A1: Serial No | B1: Hospital | C1: State | D1: Department | E1: Equipment | F1: Quantity | G1: Unit Price (USD) | H1: Supplier | I1: Supplier Country | J1: Date Ordered | K1: Date Delivered | L1: Maintenance Cost (USD/year) | M1: Installation Cost (USD) | N1: Equipment Condition
A2: 1 | B2: Lagos General | C2: Lagos | D2: Cardiology | E2: ECG Machine | F2: 2 | G2: 5000 | H2: MedTech Inc. | I2: USA | J2: 45366 | K2: 45392 | L2: 1000 | M2: 500 | N2: New
A3: 2 | B3: Abuja Hospital | C3: Abuja | D3: Radiology | E3: MRI Machine | F3: 1 | G3: 15000 | H3: Imagix | I3: UK | J3: 45342 | K3: 45369 | L3: 2000 | M3: 1000 | N3: New
A4: 3 | B4: Kano Medical | C4: Kano | D4: Surgery | E4: Surgical Tools | F4: 5 | G4: 300 | H4: SurgiSupplies | I4: UAE | J4: 45301 | K4: 45327 | L4: 500 | M4: 200 | N4: Used - Good
A5: 4 | B5: Port Harcourt | C5: Rivers | D5: Pediatrics | E5: Ventilator | F5: 3 | G5: 10000 | H5: RespCare | I5: China | J5: 45384 | K5: 45407 | L5: 1500 | M5: 800 | N5: Refurbished
A6: 5 | B6: Ibadan Clinic | C6: Oyo | D6: Obstetrics | E6: Ultrasound | F6: 1 | G6: 8000 | H6: Sonoscan | I6: Japan | J6: 45356 | K6: 45379 | L6: 1200 | M6: 600 | N6: New
A7: 6 | B7: Kaduna Clinic | C7: Kaduna | D7: Oncology | E7: Radiation Machine | F7: 1 | G7: 200000 | H7: RadSource | I7: Germany | J7: 45392 | K7: 45417 | L7: 5000 | M7: 2000 | N7: New
A8: 7 | B8: Enugu General | C8: Enugu | D8: Neurology | E8: EEG Machine | F8: 2 | G8: 10000 | H8: NeuroTech | I8: Spain | J8: 45350 | K8: 45376 | L8: 1500 | M8: 1000 | N8: Refurbished
A9: 8 | B9: Benin City Hosp | C9: Edo | D9: Orthopedics | E9: X-ray Machine | F9: 1 | G9: 25000 | H9: MedImaging | I9: France | J9: 45371 | K9: 45397 | L9: 2000 | M9: 1200 | N9: New
A10: 9 | B10: Owerri Medical | C10: Imo | D10: Urology | E10: Lithotripter | F10: 1 | G10: 75000 | H10: UltraMed | I10: India | J10: 45316 | K10: 45342 | L10: 3000 | M10: 1500 | N10: New
A11: 10 | B11: Jos Teaching | C11: Plateau | D11: Hematology | E11: Hematology Analyzer | F11: 2 | G11: 30000 | H11: HemoTech | I11: USA | J11: 45387 | K11: 45412 | L11: 1000 | M11: 800 | N11: New
A12: 11 | B12: Warri General | C12: Delta | D12: Emergency Care | E12: Defibrillator | F12: 3 | G12: 5000 | H12: LifeSaver | I12: USA | J12: 45366 | K12: 45392 | L12: 1000 | M12: 500 | N12: New
A13: 12 | B13: Calabar Medical | C13: Cross River | D13: Gynecology | E13: Colposcope | F13: 1 | G13: 8000 | H13: GynoTech | I13: Mexico | J13: 45342 | K13: 45369 | L13: 1200 | M13: 700 | N13: Refurbished
... A261: 260 | B261: Dutse General Hospital | C261: Jigawa | D261: Emergency Care | E261: Defibrillator | F261: 3 | G261: 10000 | H261: CardiaTech | I261: USA | J261: 45369 | K261: 45394 | L261: 1200 | M261: 800 | N261: New

Sheet pivot analyser
Q1: quantity of equipment supplied by different countries
C2: Row Labels | D2: Total maintence cost per year | Q2: Row Labels | R2: Sum of Quantity
A3: Total Equipment Procured | C3: MRI Machine | D3: 57000 | Q3: Australia | R3: 163 | U3: =Q3 -> Australia | V3: =R3 -> 163
A4: 612 | C4: CT Scanner | D4: 41000 | Q4: USA | R4: 118 | U4: =Q4 -> USA | V4: =R4 -> 118
C5: Anesthesia Machine | D5: 40000 | Q5: UAE | R5: 94 | U5: =Q5 -> UAE | V5: =R5 -> 94
C6: Ventilator | D6: 33000 | Q6: Germany | R6: 60 | U6: =Q6 -> Germany | V6: =R6 -> 60
A7: Total Procurement Cost | C7: Operating Table | D7: 32600 | Q7: France | R7: 59 | U7: =Q7 -> France | V7: =R7 -> 59
A8: 20910500 | C8: Grand Total | D8: 203600 | Q8: Grand Total | R8: 494
A11: Average Unit Price | C11: top 5 equipment with high maintenece cost
A12: 37405 | C12: Row Labels | D12: Total maintence cost per year | G12: Sum of Quantity | H12: Column Labels
C13: MRI Machine | D13: 57000 | G13: Row Labels | H13: New | I13: Refurbished | J13: Used - Fair | K13: Used - Good | L13: Grand Total
C14: CT Scanner | D14: 41000 | G14: Cardiology | H14: 4 | I14: 2 | J14: 2 | K14: 3 | L14: 11
A15: Average Delivery Time | C15: Anesthesia Machine | D15: 40000 | G15: Dermatology | H15: 1 | I15: 1 | L15: 2
A16: 25.296154 | C16: Ventilator | D16: 33000 | G16: Emergency Care | H16: 110 | I16: 2 | L16: 112
C17: Operating Table | D17: 32600 | G17: ENT | H17: 3 | J17: 7 | L17: 10
C18: Grand Total | D18: 203600 | G18: Gastroenterology | H18: 4 | L18: 4 | Q18: equipment condition by installation cost
A19: Total maintence cost per year | G19: Gynecology | H19: 3 | I19: 1 | L19: 4 | Q19: Row Labels | R19: Total Installation Cost
A20: 462600 | C20: =C13 -> MRI Machine | D20: =D13 -> 57000 | G20: Hematology | H20: 4 | I20: 8 | L20: 12 | Q20: New | R20: 181100 | U20: =Q20 -> New | V20: =R20 -> 181100
C21: =C14 -> CT Scanner | D21: =D14 -> 41000 | G21: Nephrology | H21: 2 | L21: 2 | Q21: Refurbished | R21: 36400 | U21: =Q21 -> Refurbished | V21: =R21 -> 36400
C22: =C15 -> Anesthesia Machine | D22: =D15 -> 40000 | G22: Neurology | H22: 4 | I22: 2 | L22: 6 | Q22: Used - Fair | R22: 3800 | U22: =Q22 -> Used - Fair | V22: =R22 -> 3800
A23: Total Installation Cost | C23: =C16 -> Ventilator | D23: =D16 -> 33000 | G23: Neurosurgery | H23: 3 | I23: 1 | L23: 4 | Q23: Used - Good | R23: 54400 | U23: =Q23 -> Used - Good | V23: =R23 -> 54400
A24: 275700 | C24: =C17 -> Operating Table | D24: =D17 -> 32600 | G24: Obstetrics | H24: 1 | J24: 2 | L24: 3 | Q24: Grand Total | R24: 275700
A25: 1 | G25: Oncology | H25: 3 | K25: 4 | L25: 7
A26: Top 5 Hospital by procurement cost | G26: Ophthalmology | H26: 1 | L26: 1
A27: Row Labels | B27: Total Procurement Cost | G27: Orthopedics | H27: 3 | I27: 2 | J27: 1 | L27: 6 | Q27: top 5 equipment with | R27: high procurement cost
A28: Minna Federal Medical Center | B28: 1815000 | G28: Pediatrics | I28: 5 | K28: 159 | L28: 164 | Q28: Row Labels | R28: Total Procurement Cost
A29: Yenagoa Medical Center | B29: 1434000 | G29: Psychiatry | I29: 1 | J29: 6 | L29: 7 | Q29: CT Scanner | R29: 4680000 | U29: =Q29 -> CT Scanner | V29: =R29 -> 4680000
A30: Dutse General Hospital | B30: 1335000 | G30: Pulmonology | H30: 2 | K30: 7 | L30: 9 | Q30: X-ray Machine | R30: 1405000 | U30: =Q30 -> X-ray Machine | V30: =R30 -> 1405000
A31: Benin City General Hospital | B31: 1274000 | G31: Radiology | H31: 94 | I31: 45 | K31: 1 | L31: 140 | Q31: Defibrillator | R31: 735000 | U31: =Q31 -> Defibrillator | V31: =R31 -> 735000
A32: Gusau General Hospital | B32: 1230000 | G32: Rheumatology | I32: 1 | L32: 1 | Q32: Infant Incubator | R32: 488000 | U32: =Q32 -> Infant Incubator | V32: =R32 -> 488000
A33: Grand Total | B33: 7088000 | G33: Surgery | H33: 52 | I33: 4 | K33: 48 | L33: 104 | Q33: Phototherapy Unit | R33: 255000 | U33: =Q33 -> Phototherapy Unit | V33: =R33 -> 255000
G34: Urology | H34: 1 | I34: 2 | L34: 3 | Q34: Grand Total | R34: 7563000
G35: Grand Total | H35: 295 | I35: 77 | J35: 18 | K35: 222 | L35: 612 | Q35: top 5 equipment with total Quantity | R35: demanded
Q36: Row Labels | R36: Sum of Quantity
E37: =I13 -> Refurbished | F37: =J13 -> Used - Fair | H37: Top 5 department by conditon of equipment | Q37: Defibrillator | R37: 75
E38: =I14 -> 2 | F38: =J14 -> 2 | H38: =G13 -> Row Labels | I38: =H13 -> New | Q38: Infant Incubator | R38: 61
E39: =I15 -> 1 | F39: =J15 -> 0 | H39: =G14 -> Cardiology | I39: =H14 -> 4 | Q39: CT Scanner | R39: 57
E40: =E7 -> 0 | F40: =F7 -> 0 | H40: =G15 -> Dermatology | I40: =H15 -> 1 | Q40: Phototherapy Unit | R40: 51
A41: 2 | E41: =E8 -> 0 | F41: =F8 -> 0 | H41: =C7 -> Operating Table | I41: =D7 -> 32600 | Q41: X-ray Machine | R41: 47
A42: equipment supplier by country | E42: =E9 -> 0 | F42: =F9 -> 0 | H42: =C8 -> Grand Total | I42: =D8 -> 203600 | Q42: Grand Total | R42: 291
...

Sheet dashboard
B6: =GETPIVOTDATA("[Measures].[Total Equipment Procured]",'pivot analyser'!$A$3) -> 612 | F6: =GETPIVOTDATA("[Measures].[Total Procurement Cost]",'pivot analyser'!$A$7) -> 20910500 | J6: =GETPIVOTDATA("[Measures].[Average Unit Price]",'pivot analyser'!$A$11) -> 37405 | N6: =GETPIVOTDATA("[Measures].[Average Delivery Time]",'pivot analyser'!$A$15) -> 25.296154 | O6: DAYS | Q6: =GETPIVOTDATA("[Measures].[Total maintence cost per year]",'pivot analyser'!$A$19) -> 462600 | V6: =GETPIVOTDATA("[Measures].[Total Installation Cost]",'pivot analyser'!$A$23) -> 275700
C15: =GETPIVOTDATA("[Measures].[Total Equipment Procured]",'pivot analyser'!$A$3) -> 612

Sheet Insight and Recommendations
